<robot name="vs060">
	<gazebo>
		<plugin filename="libgazebo_ros_control.so" name="gazebo_ros_control">
			<robotNamespace>/vs060</robotNamespace>
		</plugin>
	</gazebo>
	<link name="world" />
	<joint name="joint_w" type="fixed">
		<parent link="world" />
		<child link="base_link" />
	</joint>
	<link name="base_link">
		<visual>
			<origin rpy="0 0 0" xyz="0 0 0" />
			<geometry>
				<mesh filename="package://denso_robot_descriptions/vs060_description/base_link.dae" scale="1 1 1" />
			</geometry>
		</visual>
		<collision>
			<origin rpy="0 0 0" xyz="0 0 0" />
			<geometry>
				<mesh filename="package://denso_robot_descriptions/vs060_description/base_link.dae" scale="1 1 1" />
			</geometry>
		</collision>
		<inertial>
			<mass value="1" />
			<origin rpy="0.000000 0.000000 0.000000" xyz="0.000000 0.000000 0.000000" />
			<inertia ixx="1" ixy="0" ixz="0" iyy="1" iyz="0" izz="1" />
		</inertial>
	</link>
	<link name="J1">
		<visual>
			<origin rpy="0 0 0" xyz="0 0 0" />
			<geometry>
				<mesh filename="package://denso_robot_descriptions/vs060_description/J1.dae" scale="1 1 1" />
			</geometry>
		</visual>
		<collision>
			<origin rpy="0 0 0" xyz="0 0 0" />
			<geometry>
				<mesh filename="package://denso_robot_descriptions/vs060_description/J1.dae" scale="1 1 1" />
			</geometry>
		</collision>
		<inertial>
			<mass value="1" />
			<origin rpy="0.000000 0.000000 0.000000" xyz="0.000000 0.000000 0.000000" />
			<inertia ixx="1" ixy="0" ixz="0" iyy="1" iyz="0" izz="1" />
		</inertial>
	</link>
	<joint name="joint_1" type="revolute">
		<parent link="base_link" />
		<child link="J1" />
		<origin rpy="0.000000 0.000000 0.000000" xyz="0.000000 0.000000 0.181500" />
		<axis xyz="-0.000000 -0.000000 1.000000" />
		<limit effort="1" lower="-2.96706" upper="2.96706" velocity="3.92699081698724" />
		<dynamics damping="0" friction="0" />
	</joint>
	<transmission name="trans_1">
		<type>transmission_interface/SimpleTransmission</type>
		<joint name="joint_1">
			<hardwareInterface>PositionJointInterface</hardwareInterface>
		</joint>
		<actuator name="motor_1">
			<hardwareInterface>PositionJointInterface</hardwareInterface>
			<mechanicalReduction>1</mechanicalReduction>
		</actuator>
	</transmission>
	<link name="J2">
		<visual>
			<origin rpy="0 0 0" xyz="0 0 0" />
			<geometry>
				<mesh filename="package://denso_robot_descriptions/vs060_description/J2.dae" scale="1 1 1" />
			</geometry>
		</visual>
		<collision>
			<origin rpy="0 0 0" xyz="0 0 0" />
			<geometry>
				<mesh filename="package://denso_robot_descriptions/vs060_description/J2.dae" scale="1 1 1" />
			</geometry>
		</collision>
		<inertial>
			<mass value="1" />
			<origin rpy="0.000000 0.000000 0.000000" xyz="0.000000 0.000000 0.000000" />
			<inertia ixx="1" ixy="0" ixz="0" iyy="1" iyz="0" izz="1" />
		</inertial>
	</link>
	<joint name="joint_2" type="revolute">
		<parent link="J1" />
		<child link="J2" />
		<origin rpy="0.000000 0.000000 0.000000" xyz="0.000000 0.000000 0.163500" />
		<axis xyz="-0.000000 1.000000 -0.000000" />
		<limit effort="1" lower="-2.094395" upper="2.094395" velocity="2.61799387799149" />
		<dynamics damping="0" friction="0" />
	</joint>
	<transmission name="trans_2">
		<type>transmission_interface/SimpleTransmission</type>
		<joint name="joint_2">
			<hardwareInterface>PositionJointInterface</hardwareInterface>
		</joint>
		<actuator name="motor_2">
			<hardwareInterface>PositionJointInterface</hardwareInterface>
			<mechanicalReduction>1</mechanicalReduction>
		</actuator>
	</transmission>
	<link name="J3">
		<visual>
			<origin rpy="0 0 0" xyz="0 0 0" />
			<geometry>
				<mesh filename="package://denso_robot_descriptions/vs060_description/J3.dae" scale="1 1 1" />
			</geometry>
		</visual>
		<collision>
			<origin rpy="0 0 0" xyz="0 0 0" />
			<geometry>
				<mesh filename="package://denso_robot_descriptions/vs060_description/J3.dae" scale="1 1 1" />
			</geometry>
		</collision>
		<inertial>
			<mass value="1" />
			<origin rpy="0.000000 0.000000 0.000000" xyz="0.000000 0.000000 0.000000" />
			<inertia ixx="1" ixy="0" ixz="0" iyy="1" iyz="0" izz="1" />
		</inertial>
	</link>
	<joint name="joint_3" type="revolute">
		<parent link="J2" />
		<child link="J3" />
		<origin rpy="0.000000 0.000000 0.000000" xyz="0.000000 0.000000 0.305000" />
		<axis xyz="-0.000000 1.000000 -0.000000" />
		<limit effort="1" lower="-2.181662" upper="2.70526" velocity="2.85832571599111" />
		<dynamics damping="0" friction="0" />
	</joint>
	<transmission name="trans_3">
		<type>transmission_interface/SimpleTransmission</type>
		<joint name="joint_3">
			<hardwareInterface>PositionJointInterface</hardwareInterface>
		</joint>
		<actuator name="motor_3">
			<hardwareInterface>PositionJointInterface</hardwareInterface>
			<mechanicalReduction>1</mechanicalReduction>
		</actuator>
	</transmission>
	<link name="J4">
		<visual>
			<origin rpy="0 0 0" xyz="0 0 0" />
			<geometry>
				<mesh filename="package://denso_robot_descriptions/vs060_description/J4.dae" scale="1 1 1" />
			</geometry>
		</visual>
		<collision>
			<origin rpy="0 0 0" xyz="0 0 0" />
			<geometry>
				<mesh filename="package://denso_robot_descriptions/vs060_description/J4.dae" scale="1 1 1" />
			</geometry>
		</collision>
		<inertial>
			<mass value="1" />
			<origin rpy="0.000000 0.000000 0.000000" xyz="0.000000 0.000000 0.000000" />
			<inertia ixx="1" ixy="0" ixz="0" iyy="1" iyz="0" izz="1" />
		</inertial>
	</link>
	<joint name="joint_4" type="revolute">
		<parent link="J3" />
		<child link="J4" />
		<origin rpy="0.000000 0.000000 0.000000" xyz="-0.010000 0.000000 0.164500" />
		<axis xyz="-0.000000 -0.000000 1.000000" />
		<limit effort="1" lower="-4.712389" upper="4.712389" velocity="3.92699081698724" />
		<dynamics damping="0" friction="0" />
	</joint>
	<transmission name="trans_4">
		<type>transmission_interface/SimpleTransmission</type>
		<joint name="joint_4">
			<hardwareInterface>PositionJointInterface</hardwareInterface>
		</joint>
		<actuator name="motor_4">
			<hardwareInterface>PositionJointInterface</hardwareInterface>
			<mechanicalReduction>1</mechanicalReduction>
		</actuator>
	</transmission>
	<link name="J5">
		<visual>
			<origin rpy="0 0 0" xyz="0 0 0" />
			<geometry>
				<mesh filename="package://denso_robot_descriptions/vs060_description/J5.dae" scale="1 1 1" />
			</geometry>
		</visual>
		<collision>
			<origin rpy="0 0 0" xyz="0 0 0" />
			<geometry>
				<mesh filename="package://denso_robot_descriptions/vs060_description/J5.dae" scale="1 1 1" />
			</geometry>
		</collision>
		<inertial>
			<mass value="1" />
			<origin rpy="0.000000 0.000000 0.000000" xyz="0.000000 0.000000 0.000000" />
			<inertia ixx="1" ixy="0" ixz="0" iyy="1" iyz="0" izz="1" />
		</inertial>
	</link>
	<joint name="joint_5" type="revolute">
		<parent link="J4" />
		<child link="J5" />
		<origin rpy="0.000000 0.000000 0.000000" xyz="0.000000 0.000000 0.135500" />
		<axis xyz="-0.000000 1.000000 -0.000000" />
		<limit effort="1" lower="-2.094395" upper="2.094395" velocity="3.02168853397778" />
		<dynamics damping="0" friction="0" />
	</joint>
	<transmission name="trans_5">
		<type>transmission_interface/SimpleTransmission</type>
		<joint name="joint_5">
			<hardwareInterface>PositionJointInterface</hardwareInterface>
		</joint>
		<actuator name="motor_5">
			<hardwareInterface>PositionJointInterface</hardwareInterface>
			<mechanicalReduction>1</mechanicalReduction>
		</actuator>
	</transmission>
	<link name="J6">
		<visual>
			<origin rpy="0 0 0" xyz="0 0 0" />
			<geometry>
				<mesh filename="package://denso_robot_descriptions/vs060_description/J6.dae" scale="1 1 1" />
			</geometry>
		</visual>
		<collision>
			<origin rpy="0 0 0" xyz="0 0 0" />
			<geometry>
				<mesh filename="package://denso_robot_descriptions/vs060_description/J6.dae" scale="1 1 1" />
			</geometry>
		</collision>
		<inertial>
			<mass value="1" />
			<origin rpy="0.000000 0.000000 0.000000" xyz="0.000000 0.000000 0.000000" />
			<inertia ixx="1" ixy="0" ixz="0" iyy="1" iyz="0" izz="1" />
		</inertial>
	</link>
	<joint name="joint_6" type="revolute">
		<parent link="J5" />
		<child link="J6" />
		<origin rpy="0.000000 0.000000 0.000000" xyz="0.000000 0.000000 0.070000" />
		<axis xyz="-0.000000 -0.000000 1.000000" />
		<limit effort="1" lower="-6.283185" upper="6.283185" velocity="6.28318530717959" />
		<dynamics damping="0" friction="0" />
	</joint>
	<transmission name="trans_6">
		<type>transmission_interface/SimpleTransmission</type>
		<joint name="joint_6">
			<hardwareInterface>PositionJointInterface</hardwareInterface>
		</joint>
		<actuator name="motor_6">
			<hardwareInterface>PositionJointInterface</hardwareInterface>
			<mechanicalReduction>1</mechanicalReduction>
		</actuator>
	</transmission>
	
	<!-- camera_link -->
	<link name="camera_link">
		<visual>
			<origin xyz="0 0 0" rpy="0 0 0"/>
			<geometry>
				<box size="0.075 0.060 0.030"/>
			</geometry>
			<material name="gray">
            	<color rgba="0.5 0.2 0.2 1.0"/>
        	</material>
		</visual>

		<collision>
			<origin xyz="0 0 0" rpy="0 0 0"/>
			<geometry>
				<box size="0.075 0.060 0.030"/>
			</geometry>
		</collision>

		<inertial>
			<mass value="1e-5" />
			<origin xyz="0 0 0" rpy="0 0 0"/>
			<inertia ixx="1e-6" ixy="0" ixz="0" iyy="1e-6" iyz="0" izz="1e-6" />
		</inertial>
	</link>

	<joint name="camera_joint" type="fixed">
		<axis xyz="1 0 0" />
		<origin xyz="0 0 0.05" rpy="0 -1.5707963 0"/>
		<!-- <origin xyz="0 0 0.05" rpy="-1.5707963 0 -1.5707963"/> -->
		<parent link="J6"/>
		<child link="camera_link"/>
	</joint>

	<!-- generate an optical frame http://www.ros.org/reps/rep-0103.html#suffix-frames
      so that ros and opencv can operate on the camera frame correctly -->
	<joint name="camera_optical_joint" type="fixed">
		<!-- these values have to be these values otherwise the gazebo camera image
			won't be aligned properly with the frame it is supposedly originating from -->
		<origin xyz="0 0 0" rpy="-1.5707963 0 -1.5707963"/>
		<!-- <origin xyz="0 0 0" rpy="0 0 0"/> -->
		<parent link="camera_link"/>
		<child link="camera_link_optical"/>
	</joint>

	<link name="camera_link_optical">
	</link>

    <gazebo reference="camera_link">
      <sensor type="camera" name="basler">
		<always_on>1</always_on>
        <update_rate>30.0</update_rate>
		<visualize>true</visualize>
        <camera>
          	<horizontal_fov>0.70288959</horizontal_fov>
			<!-- <horizontal_fov>1.570796327</horizontal_fov> -->
			<image>
				<width>2592</width>
				<height>1944</height>
				<format>R8G8B8</format>
			</image>
			<save enabled="true">
				<path>/tmp/camera_save_tutorial</path>
			</save>
          	<clip>
				<near>0.001</near>
				<far>10</far>
          	</clip>
			<noise>
				<type>gaussian</type>
				<!-- Noise is sampled independently per pixel on each frame.
					That pixel's noise value is added to each of its color
					channels, which at that point lie in the range [0,1]. -->
				<mean>0.0</mean>
				<stddev>0.007</stddev>
        	</noise>
        </camera>

        <plugin name="camera_camera_controller" filename="libgazebo_ros_camera.so">
			<alwaysOn>true</alwaysOn>
			<updateRate>30.0</updateRate>
			<cameraName>arm_sensor/camera</cameraName>
			<imageTopicName>image_raw</imageTopicName>
			<cameraInfoTopicName>camera_info</cameraInfoTopicName>
			<frameName>camera_link</frameName>
			<hackBaseline>0.0</hackBaseline>
			<distortionK1>0.0</distortionK1>
			<distortionK2>0.0</distortionK2>
			<distortionK3>0.0</distortionK3>
			<distortionT1>0.0</distortionT1>
			<distortionT2>0.0</distortionT2>
			<CxPrime>1296</CxPrime>
			<Cx>1296</Cx>
			<Cy>972</Cy>
			<focalLength>0.3</focalLength>
        </plugin>
      </sensor>
    </gazebo>

	<link name="pattern">
		<visual>
			<origin rpy="0 0 0" xyz="0 0 0" />
			<geometry>
				<mesh filename="package://denso_robot_descriptions/vs060_description/pattern.dae" scale="1 1 1" />
			</geometry>
		</visual>
		<collision>
			<origin rpy="0 0 0" xyz="0 0 0" />
			<geometry>
				<box size="0.22 0.18 0.002"/> 
			</geometry>
		</collision>
		<inertial>
			<mass value="1" />
			<origin rpy="0.000000 0.000000 0.000000" xyz="0.000000 0.000000 0.000000" />
			<inertia ixx="1" ixy="0" ixz="0" iyy="1" iyz="0" izz="1" />
		</inertial>
	</link>

	<joint name="joint_pattern" type="fixed">
		<parent link="world" />
		<child link="pattern" />
		<origin rpy="0.000000 0.000000 1.5707963" xyz="0.300000 0.000000 0.001" />
	</joint>

	<!-- Add emissive light in pattern self -->
	<gazebo reference="pattern">
		<visual>
			<material>
				<emissive>0.5 0.5 0.5 0.5</emissive>
				<shader type='vertex'>
					<normal_map>__default__</normal_map>
				</shader>
			</material>
		</visual>
	</gazebo>
</robot>